[2024-04-03T10:16:52.609+0200] {taskinstance.py:1159} INFO - Dependencies all met for dep_context=non-requeueable deps ti=<TaskInstance: daily_actualization.actualize manual__2024-04-03T08:16:50.821295+00:00 [queued]>
[2024-04-03T10:16:52.612+0200] {taskinstance.py:1159} INFO - Dependencies all met for dep_context=requeueable deps ti=<TaskInstance: daily_actualization.actualize manual__2024-04-03T08:16:50.821295+00:00 [queued]>
[2024-04-03T10:16:52.612+0200] {taskinstance.py:1361} INFO - Starting attempt 1 of 1
[2024-04-03T10:16:52.620+0200] {taskinstance.py:1382} INFO - Executing <Task(BashOperator): actualize> on 2024-04-03 08:16:50.821295+00:00
[2024-04-03T10:16:52.623+0200] {standard_task_runner.py:57} INFO - Started process 99852 to run task
[2024-04-03T10:16:52.625+0200] {standard_task_runner.py:84} INFO - Running: ['airflow', 'tasks', 'run', 'daily_actualization', 'actualize', 'manual__2024-04-03T08:16:50.821295+00:00', '--job-id', '29', '--raw', '--subdir', '/home/lucas/Data Science/Project NBA/dags/dag_airflow.py', '--cfg-path', '/tmp/tmponr5vbtg']
[2024-04-03T10:16:52.626+0200] {standard_task_runner.py:85} INFO - Job 29: Subtask actualize
[2024-04-03T10:16:52.644+0200] {task_command.py:416} INFO - Running <TaskInstance: daily_actualization.actualize manual__2024-04-03T08:16:50.821295+00:00 [running]> on host ASUS-LEK
[2024-04-03T10:16:52.671+0200] {taskinstance.py:1662} INFO - Exporting env vars: AIRFLOW_CTX_DAG_OWNER='airflow' AIRFLOW_CTX_DAG_ID='daily_actualization' AIRFLOW_CTX_TASK_ID='actualize' AIRFLOW_CTX_EXECUTION_DATE='2024-04-03T08:16:50.821295+00:00' AIRFLOW_CTX_TRY_NUMBER='1' AIRFLOW_CTX_DAG_RUN_ID='manual__2024-04-03T08:16:50.821295+00:00'
[2024-04-03T10:16:52.672+0200] {subprocess.py:63} INFO - Tmp dir root location: /tmp
[2024-04-03T10:16:52.673+0200] {subprocess.py:75} INFO - Running command: ['/usr/bin/bash', '-c', "python3 '/home/lucas/Data Science/Project NBA/actualize.py'"]
[2024-04-03T10:16:52.680+0200] {subprocess.py:86} INFO - Output:
[2024-04-03T10:17:03.243+0200] {subprocess.py:93} INFO - /home/lucas/anaconda3/lib/python3.11/site-packages/google/auth/_default.py:76: UserWarning: Your application has authenticated using end user credentials from Google Cloud SDK without a quota project. You might receive a "quota exceeded" or "API not enabled" error. See the following page for troubleshooting: https://cloud.google.com/docs/authentication/adc-troubleshooting/user-creds.
[2024-04-03T10:17:03.243+0200] {subprocess.py:93} INFO -   warnings.warn(_CLOUD_SDK_CREDENTIALS_WARNING)
[2024-04-03T10:17:03.588+0200] {subprocess.py:93} INFO - Traceback (most recent call last):
[2024-04-03T10:17:03.589+0200] {subprocess.py:93} INFO -   File "/home/lucas/Data Science/Project NBA/actualize.py", line 34, in <module>
[2024-04-03T10:17:03.589+0200] {subprocess.py:93} INFO -     etl.upload_to_bucket(
[2024-04-03T10:17:03.589+0200] {subprocess.py:93} INFO -   File "/home/lucas/Data Science/Project NBA/etl.py", line 285, in upload_to_bucket
[2024-04-03T10:17:03.589+0200] {subprocess.py:93} INFO -     storage_client = storage.Client()
[2024-04-03T10:17:03.589+0200] {subprocess.py:93} INFO -                      ^^^^^^^^^^^^^^^^
[2024-04-03T10:17:03.589+0200] {subprocess.py:93} INFO -   File "/home/lucas/anaconda3/lib/python3.11/site-packages/google/cloud/storage/client.py", line 226, in __init__
[2024-04-03T10:17:03.589+0200] {subprocess.py:93} INFO -     super(Client, self).__init__(
[2024-04-03T10:17:03.589+0200] {subprocess.py:93} INFO -   File "/home/lucas/anaconda3/lib/python3.11/site-packages/google/cloud/client/__init__.py", line 320, in __init__
[2024-04-03T10:17:03.590+0200] {subprocess.py:93} INFO -     _ClientProjectMixin.__init__(self, project=project, credentials=credentials)
[2024-04-03T10:17:03.590+0200] {subprocess.py:93} INFO -   File "/home/lucas/anaconda3/lib/python3.11/site-packages/google/cloud/client/__init__.py", line 271, in __init__
[2024-04-03T10:17:03.590+0200] {subprocess.py:93} INFO -     raise EnvironmentError(
[2024-04-03T10:17:03.590+0200] {subprocess.py:93} INFO - OSError: Project was not passed and could not be determined from the environment.
[2024-04-03T10:17:03.780+0200] {subprocess.py:97} INFO - Command exited with return code 1
[2024-04-03T10:17:03.784+0200] {taskinstance.py:1937} ERROR - Task failed with exception
Traceback (most recent call last):
  File "/home/lucas/anaconda3/lib/python3.11/site-packages/airflow/operators/bash.py", line 210, in execute
    raise AirflowException(
airflow.exceptions.AirflowException: Bash command failed. The command returned a non-zero exit code 1.
[2024-04-03T10:17:03.785+0200] {taskinstance.py:1400} INFO - Marking task as FAILED. dag_id=daily_actualization, task_id=actualize, execution_date=20240403T081650, start_date=20240403T081652, end_date=20240403T081703
[2024-04-03T10:17:03.794+0200] {standard_task_runner.py:104} ERROR - Failed to execute job 29 for task actualize (Bash command failed. The command returned a non-zero exit code 1.; 99852)
[2024-04-03T10:17:03.828+0200] {local_task_job_runner.py:228} INFO - Task exited with return code 1
[2024-04-03T10:17:03.833+0200] {taskinstance.py:2778} INFO - 0 downstream tasks scheduled from follow-on schedule check
